<?xml version="1.0" encoding="utf-8"?>
<!-- This URDF was automatically created by SolidWorks to URDF Exporter! Originally created by Stephen Brawner (brawner@gmail.com) 
     Commit Version: 1.6.0-4-g7f85cfe  Build Version: 1.6.7995.38578
     For more information, please see http://wiki.ros.org/sw_urdf_exporter -->
<robot
  name="manipulator_tf">
  <link
    name="base_link">
    <inertial>
      <origin
        xyz="-4.9546E-15 -0.0025 1.1984E-14"
        rpy="0 0 0" />
      <mass
        value="0.24083" />
      <inertia
        ixx="0.00057369"
        ixy="3.2157E-15"
        ixz="-1.0718E-15"
        iyy="0.0022033"
        iyz="-2.7475E-15"
        izz="0.0016306" />
    </inertial>
    <visual>
      <origin
        xyz="0 0 0"
        rpy="0 0 0" />
      <geometry>
        <mesh
          filename="package://manipulator_tf/meshes/base_link.STL" />
      </geometry>
      <material
        name="">
        <color
          rgba="0.79216 0.81961 0.93333 1" />
      </material>
    </visual>
    <collision>
      <origin
        xyz="0 0 0"
        rpy="0 0 0" />
      <geometry>
        <mesh
          filename="package://manipulator_tf/meshes/base_link.STL" />
      </geometry>
    </collision>
  </link>
  <link
    name="arm_base_link">
    <inertial>
      <origin
        xyz="0.127882844326927 0.21516198683833 0.243466478777363"
        rpy="0 0 0" />
      <mass
        value="0.0888805032863536" />
      <inertia
        ixx="7.78274568162348E-05"
        ixy="-4.51119521708741E-08"
        ixz="9.02366661508644E-13"
        iyy="0.000152787665848685"
        iyz="-6.09842163953188E-13"
        izz="8.05930936282739E-05" />
    </inertial>
    <visual>
      <origin
        xyz="0 0 0"
        rpy="0 0 0" />
      <geometry>
        <mesh
          filename="package://manipulator_tf/meshes/arm_base_link.STL" />
      </geometry>
      <material
        name="">
        <color
          rgba="0.752941176470588 0.752941176470588 0.752941176470588 1" />
      </material>
    </visual>
    <collision>
      <origin
        xyz="0 0 0"
        rpy="0 0 0" />
      <geometry>
        <mesh
          filename="package://manipulator_tf/meshes/arm_base_link.STL" />
      </geometry>
    </collision>
  </link>
  <joint
    name="arm_base_joint"
    type="fixed">
    <origin
      xyz="-0.12473 0.24347 -0.18335"
      rpy="1.5708 0 0" />
    <parent
      link="base_link" />
    <child
      link="arm_base_link" />
    <axis
      xyz="0 0 0" />
  </joint>
  <link
    name="arm_1_link">
    <inertial>
      <origin
        xyz="-0.00304007438045744 0.0196164335050423 -0.00291517432990257"
        rpy="0 0 0" />
      <mass
        value="0.102309676287535" />
      <inertia
        ixx="5.85277337608598E-05"
        ixy="-1.83034149134299E-07"
        ixz="-5.85534183280057E-07"
        iyy="0.000109918724976136"
        iyz="3.63049047266557E-07"
        izz="5.95682017970673E-05" />
    </inertial>
    <visual>
      <origin
        xyz="0 0 0"
        rpy="0 0 0" />
      <geometry>
        <mesh
          filename="package://manipulator_tf/meshes/arm_1_link.STL" />
      </geometry>
      <material
        name="">
        <color
          rgba="0.752941176470588 0.752941176470588 0.752941176470588 1" />
      </material>
    </visual>
    <collision>
      <origin
        xyz="0 0 0"
        rpy="0 0 0" />
      <geometry>
        <mesh
          filename="package://manipulator_tf/meshes/arm_1_link.STL" />
      </geometry>
    </collision>
  </link>
  <joint
    name="arm_1_joint"
    type="continuous">
    <origin
      xyz="0.12473 0.22085 0.24347"
      rpy="3.1416 1.1738 3.1416" />
    <parent
      link="arm_base_link" />
    <child
      link="arm_1_link" />
    <axis
      xyz="0 1 0" />
    <limit
      lower="-1.57"
      upper="1.57"
      effort="10"
      velocity="100" />
  </joint>
  <link
    name="arm_2_link">
    <inertial>
      <origin
        xyz="-0.00136241892661261 0.0759999999999952 0.00324974749212679"
        rpy="0 0 0" />
      <mass
        value="0.0731866074343535" />
      <inertia
        ixx="4.80073815600738E-05"
        ixy="-1.00851029729116E-08"
        ixz="8.91994561566128E-06"
        iyy="3.20760640864426E-05"
        iyz="2.40557713069729E-08"
        izz="3.04704178358834E-05" />
    </inertial>
    <visual>
      <origin
        xyz="0 0 0"
        rpy="0 0 0" />
      <geometry>
        <mesh
          filename="package://manipulator_tf/meshes/arm_2_link.STL" />
      </geometry>
      <material
        name="">
        <color
          rgba="0.752941176470588 0.752941176470588 0.752941176470588 1" />
      </material>
    </visual>
    <collision>
      <origin
        xyz="0 0 0"
        rpy="0 0 0" />
      <geometry>
        <mesh
          filename="package://manipulator_tf/meshes/arm_2_link.STL" />
      </geometry>
    </collision>
  </link>
  <joint
    name="arm_2_joint"
    type="continuous">
    <origin
      xyz="0.00057178 0.0325 0.00023971"
      rpy="0 0 0" />
    <parent
      link="arm_1_link" />
    <child
      link="arm_2_link" />
    <axis
      xyz="0.38664 0 -0.92223" />
    <limit
      lower="-1.57"
      upper="1.57"
      effort="10"
      velocity="100" />
  </joint>
  <link
    name="arm_3_link">
    <inertial>
      <origin
        xyz="-0.0025815322874481 0.0524015939543056 0.000939181171344017"
        rpy="0 0 0" />
      <mass
        value="0.103604281307373" />
      <inertia
        ixx="3.85881018738479E-05"
        ixy="-4.80398867358625E-07"
        ixz="5.05895931054358E-06"
        iyy="2.28862113904906E-05"
        iyz="-1.44453325725892E-07"
        izz="2.97794533690991E-05" />
    </inertial>
    <visual>
      <origin
        xyz="0 0 0"
        rpy="0 0 0" />
      <geometry>
        <mesh
          filename="package://manipulator_tf/meshes/arm_3_link.STL" />
      </geometry>
      <material
        name="">
        <color
          rgba="0.752941176470588 0.752941176470588 0.752941176470588 1" />
      </material>
    </visual>
    <collision>
      <origin
        xyz="0 0 0"
        rpy="0 0 0" />
      <geometry>
        <mesh
          filename="package://manipulator_tf/meshes/arm_3_link.STL" />
      </geometry>
    </collision>
  </link>
  <joint
    name="arm_3_joint"
    type="continuous">
    <origin
      xyz="0 0.152 0"
      rpy="0 0 0" />
    <parent
      link="arm_2_link" />
    <child
      link="arm_3_link" />
    <axis
      xyz="0.38664 0 -0.92223" />
    <limit
      lower="-1.57"
      upper="1.57"
      effort="10"
      velocity="100" />
  </joint>
  <link
    name="arm_4_link">
    <inertial>
      <origin
        xyz="-0.00101187414780247 0.0375011786310828 -0.00366708121412873"
        rpy="0 0 0" />
      <mass
        value="0.0995665365854079" />
      <inertia
        ixx="2.11129357002765E-05"
        ixy="-8.60510244360547E-08"
        ixz="2.61664416187348E-06"
        iyy="1.51148951315073E-05"
        iyz="-3.60758973291711E-08"
        izz="1.71059724068234E-05" />
    </inertial>
    <visual>
      <origin
        xyz="0 0 0"
        rpy="0 0 0" />
      <geometry>
        <mesh
          filename="package://manipulator_tf/meshes/arm_4_link.STL" />
      </geometry>
      <material
        name="">
        <color
          rgba="0.752941176470588 0.752941176470588 0.752941176470588 1" />
      </material>
    </visual>
    <collision>
      <origin
        xyz="0 0 0"
        rpy="0 0 0" />
      <geometry>
        <mesh
          filename="package://manipulator_tf/meshes/arm_4_link.STL" />
      </geometry>
    </collision>
  </link>
  <joint
    name="arm_4_joint"
    type="continuous">
    <origin
      xyz="0 0.1464 0"
      rpy="0 0 0" />
    <parent
      link="arm_3_link" />
    <child
      link="arm_4_link" />
    <axis
      xyz="0.38664 0 -0.92223" />
    <limit
      lower="-1.57"
      upper="1.57"
      effort="10"
      velocity="100" />
  </joint>
  <link
    name="arm_5_link">
    <inertial>
      <origin
        xyz="-0.00868940056135506 0.0276881873217658 -0.0253003257939571"
        rpy="0 0 0" />
      <mass
        value="0.0375612763479438" />
      <inertia
        ixx="6.51328878264193E-06"
        ixy="4.824257465463E-09"
        ixz="1.70111525571283E-06"
        iyy="6.43248404947121E-06"
        iyz="-9.59375877533994E-09"
        izz="2.9512265950098E-06" />
    </inertial>
    <visual>
      <origin
        xyz="0 0 0"
        rpy="0 0 0" />
      <geometry>
        <mesh
          filename="package://manipulator_tf/meshes/arm_5_link.STL" />
      </geometry>
      <material
        name="">
        <color
          rgba="0.752941176470588 0.752941176470588 0.752941176470588 1" />
      </material>
    </visual>
    <collision>
      <origin
        xyz="0 0 0"
        rpy="0 0 0" />
      <geometry>
        <mesh
          filename="package://manipulator_tf/meshes/arm_5_link.STL" />
      </geometry>
    </collision>
  </link>
  <joint
    name="arm_5_joint"
    type="continuous">
    <origin
      xyz="0.00056091 0.09115 0.0028104"
      rpy="3.1416 0 3.1416" />
    <parent
      link="arm_4_link" />
    <child
      link="arm_5_link" />
    <axis
      xyz="0 1 0" />
    <limit
      lower="-1.57"
      upper="1.57"
      effort="10"
      velocity="100" />
  </joint>
  <link
    name="gripper_1_link">
    <inertial>
      <origin
        xyz="0.000163480467086502 -0.00403983489131327 0.00336463442646602"
        rpy="0 0 0" />
      <mass
        value="0.00233893532260202" />
      <inertia
        ixx="2.44085104510321E-07"
        ixy="-4.91339632043238E-09"
        ixz="-5.73121224919762E-19"
        iyy="7.71995240694164E-08"
        iyz="2.04123577772977E-18"
        izz="3.18397565042681E-07" />
    </inertial>
    <visual>
      <origin
        xyz="0 0 0"
        rpy="0 0 0" />
      <geometry>
        <mesh
          filename="package://manipulator_tf/meshes/gripper_1_link.STL" />
      </geometry>
      <material
        name="">
        <color
          rgba="0.792156862745098 0.819607843137255 0.933333333333333 1" />
      </material>
    </visual>
    <collision>
      <origin
        xyz="0 0 0"
        rpy="0 0 0" />
      <geometry>
        <mesh
          filename="package://manipulator_tf/meshes/gripper_1_link.STL" />
      </geometry>
    </collision>
  </link>
  <joint
    name="gripper_1_joint"
    type="continuous">
    <origin
      xyz="0.0068104 0.0295 -0.011783"
      rpy="0.90777 -0.89161 2.1168" />
    <parent
      link="arm_5_link" />
    <child
      link="gripper_1_link" />
    <axis
      xyz="0 0 1" />
    <limit
      lower="-1.57"
      upper="1.57"
      effort="10"
      velocity="100" />
  </joint>
</robot>